[2024-10-30T08:00:42.967+0000] {local_task_job_runner.py:120} INFO - ::group::Pre task execution logs
[2024-10-30T08:00:42.990+0000] {taskinstance.py:2076} INFO - Dependencies all met for dep_context=non-requeueable deps ti=<TaskInstance: ETL_To_Data_Warehouse.update_measure_stage_hongheo manual__2024-10-30T08:00:36.114353+00:00 [queued]>
[2024-10-30T08:00:42.998+0000] {taskinstance.py:2076} INFO - Dependencies all met for dep_context=requeueable deps ti=<TaskInstance: ETL_To_Data_Warehouse.update_measure_stage_hongheo manual__2024-10-30T08:00:36.114353+00:00 [queued]>
[2024-10-30T08:00:42.999+0000] {taskinstance.py:2306} INFO - Starting attempt 1 of 1
[2024-10-30T08:00:43.012+0000] {taskinstance.py:2330} INFO - Executing <Task(PythonOperator): update_measure_stage_hongheo> on 2024-10-30 08:00:36.114353+00:00
[2024-10-30T08:00:43.019+0000] {standard_task_runner.py:63} INFO - Started process 13981 to run task
[2024-10-30T08:00:43.022+0000] {standard_task_runner.py:90} INFO - Running: ['***', 'tasks', 'run', 'ETL_To_Data_Warehouse', 'update_measure_stage_hongheo', 'manual__2024-10-30T08:00:36.114353+00:00', '--job-id', '62', '--raw', '--subdir', 'DAGS_FOLDER/ETL_LDTBXH.dag.py', '--cfg-path', '/tmp/tmpdlivpwr4']
[2024-10-30T08:00:43.023+0000] {standard_task_runner.py:91} INFO - Job 62: Subtask update_measure_stage_hongheo
[2024-10-30T08:00:43.266+0000] {task_command.py:426} INFO - Running <TaskInstance: ETL_To_Data_Warehouse.update_measure_stage_hongheo manual__2024-10-30T08:00:36.114353+00:00 [running]> on host 3d0ab7361361
[2024-10-30T08:00:43.349+0000] {taskinstance.py:2648} INFO - Exporting env vars: AIRFLOW_CTX_DAG_OWNER='***' AIRFLOW_CTX_DAG_ID='ETL_To_Data_Warehouse' AIRFLOW_CTX_TASK_ID='update_measure_stage_hongheo' AIRFLOW_CTX_EXECUTION_DATE='2024-10-30T08:00:36.114353+00:00' AIRFLOW_CTX_TRY_NUMBER='1' AIRFLOW_CTX_DAG_RUN_ID='manual__2024-10-30T08:00:36.114353+00:00'
[2024-10-30T08:00:43.351+0000] {taskinstance.py:430} INFO - ::endgroup::
[2024-10-30T08:02:53.600+0000] {taskinstance.py:441} INFO - ::group::Post task execution logs
[2024-10-30T08:02:53.601+0000] {taskinstance.py:2905} ERROR - Task failed with exception
Traceback (most recent call last):
  File "/home/airflow/.local/lib/python3.11/site-packages/mysql/connector/connection_cext.py", line 327, in _open_connection
    self._cmysql.connect(**cnx_kwargs)
_mysql_connector.MySQLInterfaceError: Can't connect to MySQL server on '172.19.0.2:3306' (110)

The above exception was the direct cause of the following exception:

Traceback (most recent call last):
  File "/home/airflow/.local/lib/python3.11/site-packages/airflow/models/taskinstance.py", line 465, in _execute_task
    result = _execute_callable(context=context, **execute_callable_kwargs)
             ^^^^^^^^^^^^^^^^^^^^^^^^^^^^^^^^^^^^^^^^^^^^^^^^^^^^^^^^^^^^^
  File "/home/airflow/.local/lib/python3.11/site-packages/airflow/models/taskinstance.py", line 432, in _execute_callable
    return execute_callable(context=context, **execute_callable_kwargs)
           ^^^^^^^^^^^^^^^^^^^^^^^^^^^^^^^^^^^^^^^^^^^^^^^^^^^^^^^^^^^^
  File "/home/airflow/.local/lib/python3.11/site-packages/airflow/models/baseoperator.py", line 401, in wrapper
    return func(self, *args, **kwargs)
           ^^^^^^^^^^^^^^^^^^^^^^^^^^^
  File "/home/airflow/.local/lib/python3.11/site-packages/airflow/operators/python.py", line 235, in execute
    return_value = self.execute_callable()
                   ^^^^^^^^^^^^^^^^^^^^^^^
  File "/home/airflow/.local/lib/python3.11/site-packages/airflow/operators/python.py", line 252, in execute_callable
    return self.python_callable(*self.op_args, **self.op_kwargs)
           ^^^^^^^^^^^^^^^^^^^^^^^^^^^^^^^^^^^^^^^^^^^^^^^^^^^^^
  File "/opt/airflow/plugins/HoNgheo/Transform.py", line 22, in run_transform_fact_hongheo
    conn = mysql.connector.connect(
           ^^^^^^^^^^^^^^^^^^^^^^^^
  File "/home/airflow/.local/lib/python3.11/site-packages/mysql/connector/pooling.py", line 322, in connect
    return CMySQLConnection(*args, **kwargs)
           ^^^^^^^^^^^^^^^^^^^^^^^^^^^^^^^^^
  File "/home/airflow/.local/lib/python3.11/site-packages/mysql/connector/connection_cext.py", line 144, in __init__
    self.connect(**kwargs)
  File "/home/airflow/.local/lib/python3.11/site-packages/mysql/connector/abstracts.py", line 1360, in connect
    self._open_connection()
  File "/home/airflow/.local/lib/python3.11/site-packages/mysql/connector/connection_cext.py", line 332, in _open_connection
    raise get_mysql_exception(
mysql.connector.errors.DatabaseError: 2003 (HY000): Can't connect to MySQL server on '172.19.0.2:3306' (110)
[2024-10-30T08:02:53.616+0000] {taskinstance.py:1206} INFO - Marking task as FAILED. dag_id=ETL_To_Data_Warehouse, task_id=update_measure_stage_hongheo, run_id=manual__2024-10-30T08:00:36.114353+00:00, execution_date=20241030T080036, start_date=20241030T080042, end_date=20241030T080253
[2024-10-30T08:02:53.628+0000] {standard_task_runner.py:110} ERROR - Failed to execute job 62 for task update_measure_stage_hongheo (2003 (HY000): Can't connect to MySQL server on '172.19.0.2:3306' (110); 13981)
[2024-10-30T08:02:53.669+0000] {local_task_job_runner.py:240} INFO - Task exited with return code 1
[2024-10-30T08:02:53.688+0000] {taskinstance.py:3503} INFO - 0 downstream tasks scheduled from follow-on schedule check
[2024-10-30T08:02:53.694+0000] {local_task_job_runner.py:222} INFO - ::endgroup::
