[2024-10-30T04:22:25.547+0000] {local_task_job_runner.py:120} INFO - ::group::Pre task execution logs
[2024-10-30T04:22:25.570+0000] {taskinstance.py:2076} INFO - Dependencies all met for dep_context=non-requeueable deps ti=<TaskInstance: ETL_TO_Data_Warehouse.truncate manual__2024-10-30T04:22:22.562188+00:00 [queued]>
[2024-10-30T04:22:25.579+0000] {taskinstance.py:2076} INFO - Dependencies all met for dep_context=requeueable deps ti=<TaskInstance: ETL_TO_Data_Warehouse.truncate manual__2024-10-30T04:22:22.562188+00:00 [queued]>
[2024-10-30T04:22:25.579+0000] {taskinstance.py:2306} INFO - Starting attempt 1 of 1
[2024-10-30T04:22:25.589+0000] {taskinstance.py:2330} INFO - Executing <Task(SQLExecuteQueryOperator): truncate> on 2024-10-30 04:22:22.562188+00:00
[2024-10-30T04:22:25.595+0000] {standard_task_runner.py:63} INFO - Started process 13412 to run task
[2024-10-30T04:22:25.598+0000] {standard_task_runner.py:90} INFO - Running: ['***', 'tasks', 'run', 'ETL_TO_Data_Warehouse', 'truncate', 'manual__2024-10-30T04:22:22.562188+00:00', '--job-id', '10', '--raw', '--subdir', 'DAGS_FOLDER/ETL_LDTBXH.dag.py', '--cfg-path', '/tmp/tmpewva40kj']
[2024-10-30T04:22:25.600+0000] {standard_task_runner.py:91} INFO - Job 10: Subtask truncate
[2024-10-30T04:22:25.648+0000] {task_command.py:426} INFO - Running <TaskInstance: ETL_TO_Data_Warehouse.truncate manual__2024-10-30T04:22:22.562188+00:00 [running]> on host 3d0ab7361361
[2024-10-30T04:22:25.722+0000] {taskinstance.py:2648} INFO - Exporting env vars: AIRFLOW_CTX_DAG_OWNER='***' AIRFLOW_CTX_DAG_ID='ETL_TO_Data_Warehouse' AIRFLOW_CTX_TASK_ID='truncate' AIRFLOW_CTX_EXECUTION_DATE='2024-10-30T04:22:22.562188+00:00' AIRFLOW_CTX_TRY_NUMBER='1' AIRFLOW_CTX_DAG_RUN_ID='manual__2024-10-30T04:22:22.562188+00:00'
[2024-10-30T04:22:25.726+0000] {taskinstance.py:430} INFO - ::endgroup::
[2024-10-30T04:22:25.727+0000] {sql.py:276} INFO - Executing: TRUNCATE TABLE Stg_DimHoGiaDinh;
TRUNCATE TABLE Stg_DimRaSoat;
[2024-10-30T04:22:25.736+0000] {base.py:84} INFO - Using connection ID 'ldtbxh_stage' for task execution.
[2024-10-30T04:22:25.744+0000] {base.py:84} INFO - Using connection ID 'ldtbxh_stage' for task execution.
[2024-10-30T04:22:25.750+0000] {taskinstance.py:441} INFO - ::group::Post task execution logs
[2024-10-30T04:22:25.751+0000] {taskinstance.py:2905} ERROR - Task failed with exception
Traceback (most recent call last):
  File "/home/airflow/.local/lib/python3.11/site-packages/airflow/models/taskinstance.py", line 465, in _execute_task
    result = _execute_callable(context=context, **execute_callable_kwargs)
             ^^^^^^^^^^^^^^^^^^^^^^^^^^^^^^^^^^^^^^^^^^^^^^^^^^^^^^^^^^^^^
  File "/home/airflow/.local/lib/python3.11/site-packages/airflow/models/taskinstance.py", line 432, in _execute_callable
    return execute_callable(context=context, **execute_callable_kwargs)
           ^^^^^^^^^^^^^^^^^^^^^^^^^^^^^^^^^^^^^^^^^^^^^^^^^^^^^^^^^^^^
  File "/home/airflow/.local/lib/python3.11/site-packages/airflow/models/baseoperator.py", line 401, in wrapper
    return func(self, *args, **kwargs)
           ^^^^^^^^^^^^^^^^^^^^^^^^^^^
  File "/home/airflow/.local/lib/python3.11/site-packages/airflow/providers/common/sql/operators/sql.py", line 282, in execute
    output = hook.run(
             ^^^^^^^^^
  File "/home/airflow/.local/lib/python3.11/site-packages/airflow/providers/common/sql/hooks/sql.py", line 431, in run
    with self._create_autocommit_connection(autocommit) as conn:
  File "/usr/local/lib/python3.11/contextlib.py", line 137, in __enter__
    return next(self.gen)
           ^^^^^^^^^^^^^^
  File "/home/airflow/.local/lib/python3.11/site-packages/airflow/providers/common/sql/hooks/sql.py", line 551, in _create_autocommit_connection
    with closing(self.get_conn()) as conn:
                 ^^^^^^^^^^^^^^^
  File "/home/airflow/.local/lib/python3.11/site-packages/airflow/providers/mysql/hooks/mysql.py", line 196, in get_conn
    return MySQLdb.connect(**conn_config)
           ^^^^^^^^^^^^^^^^^^^^^^^^^^^^^^
  File "/home/airflow/.local/lib/python3.11/site-packages/MySQLdb/__init__.py", line 121, in Connect
    return Connection(*args, **kwargs)
           ^^^^^^^^^^^^^^^^^^^^^^^^^^^
  File "/home/airflow/.local/lib/python3.11/site-packages/MySQLdb/connections.py", line 195, in __init__
    super().__init__(*args, **kwargs2)
MySQLdb.OperationalError: (2002, "Can't connect to server on '127.0.0.1' (115)")
[2024-10-30T04:22:25.759+0000] {taskinstance.py:1206} INFO - Marking task as FAILED. dag_id=ETL_TO_Data_Warehouse, task_id=truncate, run_id=manual__2024-10-30T04:22:22.562188+00:00, execution_date=20241030T042222, start_date=20241030T042225, end_date=20241030T042225
[2024-10-30T04:22:25.768+0000] {standard_task_runner.py:110} ERROR - Failed to execute job 10 for task truncate ((2002, "Can't connect to server on '127.0.0.1' (115)"); 13412)
[2024-10-30T04:22:25.810+0000] {local_task_job_runner.py:240} INFO - Task exited with return code 1
[2024-10-30T04:22:25.830+0000] {taskinstance.py:3503} INFO - 0 downstream tasks scheduled from follow-on schedule check
[2024-10-30T04:22:25.835+0000] {local_task_job_runner.py:222} INFO - ::endgroup::
