[2024-11-12T01:25:42.738+0000] {local_task_job_runner.py:120} INFO - ::group::Pre task execution logs
[2024-11-12T01:25:42.771+0000] {taskinstance.py:2076} INFO - Dependencies all met for dep_context=non-requeueable deps ti=<TaskInstance: ETL_To_Data_Warehouse.load_data_to_stgNCC manual__2024-11-12T01:24:54.300922+00:00 [queued]>
[2024-11-12T01:25:42.780+0000] {taskinstance.py:2076} INFO - Dependencies all met for dep_context=requeueable deps ti=<TaskInstance: ETL_To_Data_Warehouse.load_data_to_stgNCC manual__2024-11-12T01:24:54.300922+00:00 [queued]>
[2024-11-12T01:25:42.780+0000] {taskinstance.py:2306} INFO - Starting attempt 1 of 1
[2024-11-12T01:25:42.794+0000] {taskinstance.py:2330} INFO - Executing <Task(PythonOperator): load_data_to_stgNCC> on 2024-11-12 01:24:54.300922+00:00
[2024-11-12T01:25:42.802+0000] {standard_task_runner.py:63} INFO - Started process 1255 to run task
[2024-11-12T01:25:42.806+0000] {standard_task_runner.py:90} INFO - Running: ['***', 'tasks', 'run', 'ETL_To_Data_Warehouse', 'load_data_to_stgNCC', 'manual__2024-11-12T01:24:54.300922+00:00', '--job-id', '611', '--raw', '--subdir', 'DAGS_FOLDER/ETL_LDTBXH.dag.py', '--cfg-path', '/tmp/tmp0kvpzs8d']
[2024-11-12T01:25:42.808+0000] {standard_task_runner.py:91} INFO - Job 611: Subtask load_data_to_stgNCC
[2024-11-12T01:25:42.856+0000] {task_command.py:426} INFO - Running <TaskInstance: ETL_To_Data_Warehouse.load_data_to_stgNCC manual__2024-11-12T01:24:54.300922+00:00 [running]> on host 3d0ab7361361
[2024-11-12T01:25:42.967+0000] {taskinstance.py:2648} INFO - Exporting env vars: AIRFLOW_CTX_DAG_OWNER='***' AIRFLOW_CTX_DAG_ID='ETL_To_Data_Warehouse' AIRFLOW_CTX_TASK_ID='load_data_to_stgNCC' AIRFLOW_CTX_EXECUTION_DATE='2024-11-12T01:24:54.300922+00:00' AIRFLOW_CTX_TRY_NUMBER='1' AIRFLOW_CTX_DAG_RUN_ID='manual__2024-11-12T01:24:54.300922+00:00'
[2024-11-12T01:25:42.969+0000] {taskinstance.py:430} INFO - ::endgroup::
[2024-11-12T01:25:43.027+0000] {logging_mixin.py:188} INFO - Kết nối đến MySQL thành công
[2024-11-12T01:25:43.039+0000] {logging_mixin.py:188} INFO - Error fetching data from API: HTTPConnectionPool(host='host.docker.internal', port=8000): Max retries exceeded with url: /NCC (Caused by NewConnectionError('<urllib3.connection.HTTPConnection object at 0x7fb5de4dca10>: Failed to establish a new connection: [Errno 101] Network is unreachable'))
[2024-11-12T01:25:43.040+0000] {logging_mixin.py:188} INFO - Không có dữ liệu để chèn.
[2024-11-12T01:25:43.040+0000] {python.py:237} INFO - Done. Returned value was: None
[2024-11-12T01:25:43.041+0000] {taskinstance.py:441} INFO - ::group::Post task execution logs
[2024-11-12T01:25:43.052+0000] {taskinstance.py:1206} INFO - Marking task as SUCCESS. dag_id=ETL_To_Data_Warehouse, task_id=load_data_to_stgNCC, run_id=manual__2024-11-12T01:24:54.300922+00:00, execution_date=20241112T012454, start_date=20241112T012542, end_date=20241112T012543
[2024-11-12T01:25:43.100+0000] {local_task_job_runner.py:240} INFO - Task exited with return code 0
[2024-11-12T01:25:43.130+0000] {taskinstance.py:3503} INFO - 1 downstream tasks scheduled from follow-on schedule check
[2024-11-12T01:25:43.132+0000] {local_task_job_runner.py:222} INFO - ::endgroup::
