[2024-10-30T09:08:04.428+0000] {local_task_job_runner.py:120} INFO - ::group::Pre task execution logs
[2024-10-30T09:08:04.452+0000] {taskinstance.py:2076} INFO - Dependencies all met for dep_context=non-requeueable deps ti=<TaskInstance: ETL_To_Data_Warehouse.load_date_stage manual__2024-10-30T09:08:01.193920+00:00 [queued]>
[2024-10-30T09:08:04.458+0000] {taskinstance.py:2076} INFO - Dependencies all met for dep_context=requeueable deps ti=<TaskInstance: ETL_To_Data_Warehouse.load_date_stage manual__2024-10-30T09:08:01.193920+00:00 [queued]>
[2024-10-30T09:08:04.459+0000] {taskinstance.py:2306} INFO - Starting attempt 1 of 1
[2024-10-30T09:08:04.470+0000] {taskinstance.py:2330} INFO - Executing <Task(PythonOperator): load_date_stage> on 2024-10-30 09:08:01.193920+00:00
[2024-10-30T09:08:04.476+0000] {standard_task_runner.py:63} INFO - Started process 9099 to run task
[2024-10-30T09:08:04.479+0000] {standard_task_runner.py:90} INFO - Running: ['***', 'tasks', 'run', 'ETL_To_Data_Warehouse', 'load_date_stage', 'manual__2024-10-30T09:08:01.193920+00:00', '--job-id', '104', '--raw', '--subdir', 'DAGS_FOLDER/ETL_LDTBXH.dag.py', '--cfg-path', '/tmp/tmpvbmb9zbd']
[2024-10-30T09:08:04.480+0000] {standard_task_runner.py:91} INFO - Job 104: Subtask load_date_stage
[2024-10-30T09:08:04.521+0000] {task_command.py:426} INFO - Running <TaskInstance: ETL_To_Data_Warehouse.load_date_stage manual__2024-10-30T09:08:01.193920+00:00 [running]> on host 3d0ab7361361
[2024-10-30T09:08:04.821+0000] {taskinstance.py:2648} INFO - Exporting env vars: AIRFLOW_CTX_DAG_OWNER='***' AIRFLOW_CTX_DAG_ID='ETL_To_Data_Warehouse' AIRFLOW_CTX_TASK_ID='load_date_stage' AIRFLOW_CTX_EXECUTION_DATE='2024-10-30T09:08:01.193920+00:00' AIRFLOW_CTX_TRY_NUMBER='1' AIRFLOW_CTX_DAG_RUN_ID='manual__2024-10-30T09:08:01.193920+00:00'
[2024-10-30T09:08:04.823+0000] {taskinstance.py:430} INFO - ::endgroup::
[2024-10-30T09:08:04.825+0000] {taskinstance.py:441} INFO - ::group::Post task execution logs
[2024-10-30T09:08:04.826+0000] {taskinstance.py:2905} ERROR - Task failed with exception
Traceback (most recent call last):
  File "/home/airflow/.local/lib/python3.11/site-packages/airflow/models/taskinstance.py", line 465, in _execute_task
    result = _execute_callable(context=context, **execute_callable_kwargs)
             ^^^^^^^^^^^^^^^^^^^^^^^^^^^^^^^^^^^^^^^^^^^^^^^^^^^^^^^^^^^^^
  File "/home/airflow/.local/lib/python3.11/site-packages/airflow/models/taskinstance.py", line 432, in _execute_callable
    return execute_callable(context=context, **execute_callable_kwargs)
           ^^^^^^^^^^^^^^^^^^^^^^^^^^^^^^^^^^^^^^^^^^^^^^^^^^^^^^^^^^^^
  File "/home/airflow/.local/lib/python3.11/site-packages/airflow/models/baseoperator.py", line 401, in wrapper
    return func(self, *args, **kwargs)
           ^^^^^^^^^^^^^^^^^^^^^^^^^^^
  File "/home/airflow/.local/lib/python3.11/site-packages/airflow/operators/python.py", line 235, in execute
    return_value = self.execute_callable()
                   ^^^^^^^^^^^^^^^^^^^^^^^
  File "/home/airflow/.local/lib/python3.11/site-packages/airflow/operators/python.py", line 252, in execute_callable
    return self.python_callable(*self.op_args, **self.op_kwargs)
           ^^^^^^^^^^^^^^^^^^^^^^^^^^^^^^^^^^^^^^^^^^^^^^^^^^^^^
  File "/opt/airflow/plugins/Date/LoadDate.py", line 6, in read_date_excel
    time_df = pd.read_excel('./Airflow/data/SampleDateDim.xls', sheet_name='LoadDates')
              ^^^^^^^^^^^^^^^^^^^^^^^^^^^^^^^^^^^^^^^^^^^^^^^^^^^^^^^^^^^^^^^^^^^^^^^^^
  File "/home/airflow/.local/lib/python3.11/site-packages/pandas/io/excel/_base.py", line 504, in read_excel
    io = ExcelFile(
         ^^^^^^^^^^
  File "/home/airflow/.local/lib/python3.11/site-packages/pandas/io/excel/_base.py", line 1563, in __init__
    ext = inspect_excel_format(
          ^^^^^^^^^^^^^^^^^^^^^
  File "/home/airflow/.local/lib/python3.11/site-packages/pandas/io/excel/_base.py", line 1419, in inspect_excel_format
    with get_handle(
         ^^^^^^^^^^^
  File "/home/airflow/.local/lib/python3.11/site-packages/pandas/io/common.py", line 872, in get_handle
    handle = open(handle, ioargs.mode)
             ^^^^^^^^^^^^^^^^^^^^^^^^^
FileNotFoundError: [Errno 2] No such file or directory: './Airflow/data/SampleDateDim.xls'
[2024-10-30T09:08:04.840+0000] {taskinstance.py:1206} INFO - Marking task as FAILED. dag_id=ETL_To_Data_Warehouse, task_id=load_date_stage, run_id=manual__2024-10-30T09:08:01.193920+00:00, execution_date=20241030T090801, start_date=20241030T090804, end_date=20241030T090804
[2024-10-30T09:08:04.850+0000] {standard_task_runner.py:110} ERROR - Failed to execute job 104 for task load_date_stage ([Errno 2] No such file or directory: './Airflow/data/SampleDateDim.xls'; 9099)
[2024-10-30T09:08:04.894+0000] {local_task_job_runner.py:240} INFO - Task exited with return code 1
[2024-10-30T09:08:04.919+0000] {taskinstance.py:3503} INFO - 0 downstream tasks scheduled from follow-on schedule check
[2024-10-30T09:08:04.923+0000] {local_task_job_runner.py:222} INFO - ::endgroup::
