[2024-10-30T07:35:31.410+0000] {local_task_job_runner.py:120} INFO - ::group::Pre task execution logs
[2024-10-30T07:35:31.434+0000] {taskinstance.py:2076} INFO - Dependencies all met for dep_context=non-requeueable deps ti=<TaskInstance: ETL_To_Data_Warehouse.update_data_stage_hongheo manual__2024-10-30T07:35:25.719506+00:00 [queued]>
[2024-10-30T07:35:31.442+0000] {taskinstance.py:2076} INFO - Dependencies all met for dep_context=requeueable deps ti=<TaskInstance: ETL_To_Data_Warehouse.update_data_stage_hongheo manual__2024-10-30T07:35:25.719506+00:00 [queued]>
[2024-10-30T07:35:31.443+0000] {taskinstance.py:2306} INFO - Starting attempt 1 of 1
[2024-10-30T07:35:31.452+0000] {taskinstance.py:2330} INFO - Executing <Task(PythonOperator): update_data_stage_hongheo> on 2024-10-30 07:35:25.719506+00:00
[2024-10-30T07:35:31.459+0000] {standard_task_runner.py:63} INFO - Started process 449 to run task
[2024-10-30T07:35:31.462+0000] {standard_task_runner.py:90} INFO - Running: ['***', 'tasks', 'run', 'ETL_To_Data_Warehouse', 'update_data_stage_hongheo', 'manual__2024-10-30T07:35:25.719506+00:00', '--job-id', '34', '--raw', '--subdir', 'DAGS_FOLDER/ETL_LDTBXH.dag.py', '--cfg-path', '/tmp/tmpcfd_34mh']
[2024-10-30T07:35:31.463+0000] {standard_task_runner.py:91} INFO - Job 34: Subtask update_data_stage_hongheo
[2024-10-30T07:35:31.504+0000] {task_command.py:426} INFO - Running <TaskInstance: ETL_To_Data_Warehouse.update_data_stage_hongheo manual__2024-10-30T07:35:25.719506+00:00 [running]> on host 3d0ab7361361
[2024-10-30T07:35:31.577+0000] {taskinstance.py:2648} INFO - Exporting env vars: AIRFLOW_CTX_DAG_OWNER='***' AIRFLOW_CTX_DAG_ID='ETL_To_Data_Warehouse' AIRFLOW_CTX_TASK_ID='update_data_stage_hongheo' AIRFLOW_CTX_EXECUTION_DATE='2024-10-30T07:35:25.719506+00:00' AIRFLOW_CTX_TRY_NUMBER='1' AIRFLOW_CTX_DAG_RUN_ID='manual__2024-10-30T07:35:25.719506+00:00'
[2024-10-30T07:35:31.579+0000] {taskinstance.py:430} INFO - ::endgroup::
[2024-10-30T07:35:31.586+0000] {taskinstance.py:441} INFO - ::group::Post task execution logs
[2024-10-30T07:35:31.586+0000] {taskinstance.py:2905} ERROR - Task failed with exception
Traceback (most recent call last):
  File "/home/airflow/.local/lib/python3.11/site-packages/mysql/connector/connection_cext.py", line 327, in _open_connection
    self._cmysql.connect(**cnx_kwargs)
_mysql_connector.MySQLInterfaceError: Can't connect to MySQL server on 'localhost:3306' (111)

The above exception was the direct cause of the following exception:

Traceback (most recent call last):
  File "/home/airflow/.local/lib/python3.11/site-packages/airflow/models/taskinstance.py", line 465, in _execute_task
    result = _execute_callable(context=context, **execute_callable_kwargs)
             ^^^^^^^^^^^^^^^^^^^^^^^^^^^^^^^^^^^^^^^^^^^^^^^^^^^^^^^^^^^^^
  File "/home/airflow/.local/lib/python3.11/site-packages/airflow/models/taskinstance.py", line 432, in _execute_callable
    return execute_callable(context=context, **execute_callable_kwargs)
           ^^^^^^^^^^^^^^^^^^^^^^^^^^^^^^^^^^^^^^^^^^^^^^^^^^^^^^^^^^^^
  File "/home/airflow/.local/lib/python3.11/site-packages/airflow/models/baseoperator.py", line 401, in wrapper
    return func(self, *args, **kwargs)
           ^^^^^^^^^^^^^^^^^^^^^^^^^^^
  File "/home/airflow/.local/lib/python3.11/site-packages/airflow/operators/python.py", line 235, in execute
    return_value = self.execute_callable()
                   ^^^^^^^^^^^^^^^^^^^^^^^
  File "/home/airflow/.local/lib/python3.11/site-packages/airflow/operators/python.py", line 252, in execute_callable
    return self.python_callable(*self.op_args, **self.op_kwargs)
           ^^^^^^^^^^^^^^^^^^^^^^^^^^^^^^^^^^^^^^^^^^^^^^^^^^^^^
  File "/opt/airflow/plugins/HoNgheo/Transform.py", line 22, in run_transform_fact_hongheo
    conn = mysql.connector.connect(
           ^^^^^^^^^^^^^^^^^^^^^^^^
  File "/home/airflow/.local/lib/python3.11/site-packages/mysql/connector/pooling.py", line 322, in connect
    return CMySQLConnection(*args, **kwargs)
           ^^^^^^^^^^^^^^^^^^^^^^^^^^^^^^^^^
  File "/home/airflow/.local/lib/python3.11/site-packages/mysql/connector/connection_cext.py", line 144, in __init__
    self.connect(**kwargs)
  File "/home/airflow/.local/lib/python3.11/site-packages/mysql/connector/abstracts.py", line 1360, in connect
    self._open_connection()
  File "/home/airflow/.local/lib/python3.11/site-packages/mysql/connector/connection_cext.py", line 332, in _open_connection
    raise get_mysql_exception(
mysql.connector.errors.DatabaseError: 2003 (HY000): Can't connect to MySQL server on 'localhost:3306' (111)
[2024-10-30T07:35:31.600+0000] {taskinstance.py:1206} INFO - Marking task as FAILED. dag_id=ETL_To_Data_Warehouse, task_id=update_data_stage_hongheo, run_id=manual__2024-10-30T07:35:25.719506+00:00, execution_date=20241030T073525, start_date=20241030T073531, end_date=20241030T073531
[2024-10-30T07:35:31.611+0000] {standard_task_runner.py:110} ERROR - Failed to execute job 34 for task update_data_stage_hongheo (2003 (HY000): Can't connect to MySQL server on 'localhost:3306' (111); 449)
[2024-10-30T07:35:31.635+0000] {local_task_job_runner.py:240} INFO - Task exited with return code 1
[2024-10-30T07:35:31.654+0000] {taskinstance.py:3503} INFO - 0 downstream tasks scheduled from follow-on schedule check
[2024-10-30T07:35:31.658+0000] {local_task_job_runner.py:222} INFO - ::endgroup::
