[2024-11-11T16:04:25.498+0000] {scheduler_job_runner.py:769} ERROR - Executor reports task instance <TaskInstance: ETL_To_Data_Warehouse.load_data_to_stgFact manual__2024-11-11T15:59:13.213689+00:00 [queued]> finished (failed) although the task says it's queued. (Info: None) Was the task killed externally?
