[2024-10-30T09:21:20.456+0000] {local_task_job_runner.py:120} INFO - ::group::Pre task execution logs
[2024-10-30T09:21:20.482+0000] {taskinstance.py:2076} INFO - Dependencies all met for dep_context=non-requeueable deps ti=<TaskInstance: ETL_To_Data_Warehouse.audit_transform manual__2024-10-30T09:21:11.804676+00:00 [queued]>
[2024-10-30T09:21:20.493+0000] {taskinstance.py:2076} INFO - Dependencies all met for dep_context=requeueable deps ti=<TaskInstance: ETL_To_Data_Warehouse.audit_transform manual__2024-10-30T09:21:11.804676+00:00 [queued]>
[2024-10-30T09:21:20.494+0000] {taskinstance.py:2306} INFO - Starting attempt 1 of 1
[2024-10-30T09:21:20.506+0000] {taskinstance.py:2330} INFO - Executing <Task(PythonOperator): audit_transform> on 2024-10-30 09:21:11.804676+00:00
[2024-10-30T09:21:20.512+0000] {standard_task_runner.py:63} INFO - Started process 2362 to run task
[2024-10-30T09:21:20.515+0000] {standard_task_runner.py:90} INFO - Running: ['***', 'tasks', 'run', 'ETL_To_Data_Warehouse', 'audit_transform', 'manual__2024-10-30T09:21:11.804676+00:00', '--job-id', '133', '--raw', '--subdir', 'DAGS_FOLDER/ETL_LDTBXH.dag.py', '--cfg-path', '/tmp/tmps3fv_pgd']
[2024-10-30T09:21:20.516+0000] {standard_task_runner.py:91} INFO - Job 133: Subtask audit_transform
[2024-10-30T09:21:20.555+0000] {task_command.py:426} INFO - Running <TaskInstance: ETL_To_Data_Warehouse.audit_transform manual__2024-10-30T09:21:11.804676+00:00 [running]> on host 3d0ab7361361
[2024-10-30T09:21:20.798+0000] {taskinstance.py:2648} INFO - Exporting env vars: AIRFLOW_CTX_DAG_OWNER='***' AIRFLOW_CTX_DAG_ID='ETL_To_Data_Warehouse' AIRFLOW_CTX_TASK_ID='audit_transform' AIRFLOW_CTX_EXECUTION_DATE='2024-10-30T09:21:11.804676+00:00' AIRFLOW_CTX_TRY_NUMBER='1' AIRFLOW_CTX_DAG_RUN_ID='manual__2024-10-30T09:21:11.804676+00:00'
[2024-10-30T09:21:20.799+0000] {taskinstance.py:430} INFO - ::endgroup::
[2024-10-30T09:21:20.848+0000] {taskinstance.py:441} INFO - ::group::Post task execution logs
[2024-10-30T09:21:20.849+0000] {taskinstance.py:2905} ERROR - Task failed with exception
Traceback (most recent call last):
  File "/home/airflow/.local/lib/python3.11/site-packages/mysql/connector/connection_cext.py", line 697, in cmd_query
    self._cmysql.query(
_mysql_connector.MySQLInterfaceError: You can't specify target table 'DimAuditForeigned' for update in FROM clause

The above exception was the direct cause of the following exception:

Traceback (most recent call last):
  File "/home/airflow/.local/lib/python3.11/site-packages/airflow/models/taskinstance.py", line 465, in _execute_task
    result = _execute_callable(context=context, **execute_callable_kwargs)
             ^^^^^^^^^^^^^^^^^^^^^^^^^^^^^^^^^^^^^^^^^^^^^^^^^^^^^^^^^^^^^
  File "/home/airflow/.local/lib/python3.11/site-packages/airflow/models/taskinstance.py", line 432, in _execute_callable
    return execute_callable(context=context, **execute_callable_kwargs)
           ^^^^^^^^^^^^^^^^^^^^^^^^^^^^^^^^^^^^^^^^^^^^^^^^^^^^^^^^^^^^
  File "/home/airflow/.local/lib/python3.11/site-packages/airflow/models/baseoperator.py", line 401, in wrapper
    return func(self, *args, **kwargs)
           ^^^^^^^^^^^^^^^^^^^^^^^^^^^
  File "/home/airflow/.local/lib/python3.11/site-packages/airflow/operators/python.py", line 235, in execute
    return_value = self.execute_callable()
                   ^^^^^^^^^^^^^^^^^^^^^^^
  File "/home/airflow/.local/lib/python3.11/site-packages/airflow/operators/python.py", line 252, in execute_callable
    return self.python_callable(*self.op_args, **self.op_kwargs)
           ^^^^^^^^^^^^^^^^^^^^^^^^^^^^^^^^^^^^^^^^^^^^^^^^^^^^^
  File "/opt/airflow/plugins/CheckAudit/Check_Audit.py", line 25, in track_transform
    cur.execute("""
  File "/home/airflow/.local/lib/python3.11/site-packages/mysql/connector/cursor_cext.py", line 372, in execute
    result = self._cnx.cmd_query(
             ^^^^^^^^^^^^^^^^^^^^
  File "/home/airflow/.local/lib/python3.11/site-packages/mysql/connector/opentelemetry/context_propagation.py", line 111, in wrapper
    result = method(cnx, *args, **kwargs)
             ^^^^^^^^^^^^^^^^^^^^^^^^^^^^
  File "/home/airflow/.local/lib/python3.11/site-packages/mysql/connector/connection_cext.py", line 705, in cmd_query
    raise get_mysql_exception(
mysql.connector.errors.DatabaseError: 1093 (HY000): You can't specify target table 'DimAuditForeigned' for update in FROM clause
[2024-10-30T09:21:20.862+0000] {taskinstance.py:1206} INFO - Marking task as FAILED. dag_id=ETL_To_Data_Warehouse, task_id=audit_transform, run_id=manual__2024-10-30T09:21:11.804676+00:00, execution_date=20241030T092111, start_date=20241030T092120, end_date=20241030T092120
[2024-10-30T09:21:20.872+0000] {standard_task_runner.py:110} ERROR - Failed to execute job 133 for task audit_transform (1093 (HY000): You can't specify target table 'DimAuditForeigned' for update in FROM clause; 2362)
[2024-10-30T09:21:20.889+0000] {local_task_job_runner.py:240} INFO - Task exited with return code 1
[2024-10-30T09:21:21.080+0000] {taskinstance.py:3503} INFO - 0 downstream tasks scheduled from follow-on schedule check
[2024-10-30T09:21:21.085+0000] {local_task_job_runner.py:222} INFO - ::endgroup::
