[2024-10-30T07:46:12.799+0000] {local_task_job_runner.py:120} INFO - ::group::Pre task execution logs
[2024-10-30T07:46:12.823+0000] {taskinstance.py:2076} INFO - Dependencies all met for dep_context=non-requeueable deps ti=<TaskInstance: ETL_To_Data_Warehouse.update_measure_stage_hongheo manual__2024-10-30T07:46:08.221990+00:00 [queued]>
[2024-10-30T07:46:12.831+0000] {taskinstance.py:2076} INFO - Dependencies all met for dep_context=requeueable deps ti=<TaskInstance: ETL_To_Data_Warehouse.update_measure_stage_hongheo manual__2024-10-30T07:46:08.221990+00:00 [queued]>
[2024-10-30T07:46:12.831+0000] {taskinstance.py:2306} INFO - Starting attempt 1 of 1
[2024-10-30T07:46:12.845+0000] {taskinstance.py:2330} INFO - Executing <Task(BashOperator): update_measure_stage_hongheo> on 2024-10-30 07:46:08.221990+00:00
[2024-10-30T07:46:12.851+0000] {standard_task_runner.py:63} INFO - Started process 6207 to run task
[2024-10-30T07:46:12.853+0000] {standard_task_runner.py:90} INFO - Running: ['***', 'tasks', 'run', 'ETL_To_Data_Warehouse', 'update_measure_stage_hongheo', 'manual__2024-10-30T07:46:08.221990+00:00', '--job-id', '50', '--raw', '--subdir', 'DAGS_FOLDER/ETL_LDTBXH.dag.py', '--cfg-path', '/tmp/tmpb1yi2psf']
[2024-10-30T07:46:12.854+0000] {standard_task_runner.py:91} INFO - Job 50: Subtask update_measure_stage_hongheo
[2024-10-30T07:46:13.060+0000] {task_command.py:426} INFO - Running <TaskInstance: ETL_To_Data_Warehouse.update_measure_stage_hongheo manual__2024-10-30T07:46:08.221990+00:00 [running]> on host 3d0ab7361361
[2024-10-30T07:46:13.127+0000] {taskinstance.py:2648} INFO - Exporting env vars: AIRFLOW_CTX_DAG_OWNER='***' AIRFLOW_CTX_DAG_ID='ETL_To_Data_Warehouse' AIRFLOW_CTX_TASK_ID='update_measure_stage_hongheo' AIRFLOW_CTX_EXECUTION_DATE='2024-10-30T07:46:08.221990+00:00' AIRFLOW_CTX_TRY_NUMBER='1' AIRFLOW_CTX_DAG_RUN_ID='manual__2024-10-30T07:46:08.221990+00:00'
[2024-10-30T07:46:13.128+0000] {taskinstance.py:430} INFO - ::endgroup::
[2024-10-30T07:46:13.129+0000] {subprocess.py:63} INFO - Tmp dir root location: /tmp
[2024-10-30T07:46:13.130+0000] {subprocess.py:75} INFO - Running command: ['/usr/bin/bash', '-c', 'python /opt/***/plugins/HoNgheo/Transform.py']
[2024-10-30T07:46:13.141+0000] {subprocess.py:86} INFO - Output:
[2024-10-30T07:46:14.466+0000] {subprocess.py:93} INFO - Traceback (most recent call last):
[2024-10-30T07:46:14.467+0000] {subprocess.py:93} INFO -   File "/home/***/.local/lib/python3.11/site-packages/mysql/connector/connection_cext.py", line 327, in _open_connection
[2024-10-30T07:46:14.470+0000] {subprocess.py:93} INFO -     self._cmysql.connect(**cnx_kwargs)
[2024-10-30T07:46:14.471+0000] {subprocess.py:93} INFO - _mysql_connector.MySQLInterfaceError: Can't connect to MySQL server on '127.0.0.1:3306' (111)
[2024-10-30T07:46:14.471+0000] {subprocess.py:93} INFO - 
[2024-10-30T07:46:14.472+0000] {subprocess.py:93} INFO - The above exception was the direct cause of the following exception:
[2024-10-30T07:46:14.472+0000] {subprocess.py:93} INFO - 
[2024-10-30T07:46:14.472+0000] {subprocess.py:93} INFO - Traceback (most recent call last):
[2024-10-30T07:46:14.472+0000] {subprocess.py:93} INFO -   File "/opt/***/plugins/HoNgheo/Transform.py", line 75, in <module>
[2024-10-30T07:46:14.473+0000] {subprocess.py:93} INFO -     run_transform_fact_hongheo()
[2024-10-30T07:46:14.473+0000] {subprocess.py:93} INFO -   File "/opt/***/plugins/HoNgheo/Transform.py", line 22, in run_transform_fact_hongheo
[2024-10-30T07:46:14.474+0000] {subprocess.py:93} INFO -     conn = mysql.connector.connect(
[2024-10-30T07:46:14.474+0000] {subprocess.py:93} INFO -            ^^^^^^^^^^^^^^^^^^^^^^^^
[2024-10-30T07:46:14.475+0000] {subprocess.py:93} INFO -   File "/home/***/.local/lib/python3.11/site-packages/mysql/connector/pooling.py", line 322, in connect
[2024-10-30T07:46:14.481+0000] {subprocess.py:93} INFO -     return CMySQLConnection(*args, **kwargs)
[2024-10-30T07:46:14.482+0000] {subprocess.py:93} INFO -            ^^^^^^^^^^^^^^^^^^^^^^^^^^^^^^^^^
[2024-10-30T07:46:14.483+0000] {subprocess.py:93} INFO -   File "/home/***/.local/lib/python3.11/site-packages/mysql/connector/connection_cext.py", line 144, in __init__
[2024-10-30T07:46:14.485+0000] {subprocess.py:93} INFO -     self.connect(**kwargs)
[2024-10-30T07:46:14.486+0000] {subprocess.py:93} INFO -   File "/home/***/.local/lib/python3.11/site-packages/mysql/connector/abstracts.py", line 1360, in connect
[2024-10-30T07:46:14.487+0000] {subprocess.py:93} INFO -     self._open_connection()
[2024-10-30T07:46:14.488+0000] {subprocess.py:93} INFO -   File "/home/***/.local/lib/python3.11/site-packages/mysql/connector/connection_cext.py", line 332, in _open_connection
[2024-10-30T07:46:14.488+0000] {subprocess.py:93} INFO -     raise get_mysql_exception(
[2024-10-30T07:46:14.489+0000] {subprocess.py:93} INFO - mysql.connector.errors.DatabaseError: 2003 (HY000): Can't connect to MySQL server on '127.0.0.1:3306' (111)
[2024-10-30T07:46:14.701+0000] {subprocess.py:97} INFO - Command exited with return code 1
[2024-10-30T07:46:14.702+0000] {taskinstance.py:441} INFO - ::group::Post task execution logs
[2024-10-30T07:46:14.711+0000] {taskinstance.py:2905} ERROR - Task failed with exception
Traceback (most recent call last):
  File "/home/airflow/.local/lib/python3.11/site-packages/airflow/models/taskinstance.py", line 465, in _execute_task
    result = _execute_callable(context=context, **execute_callable_kwargs)
             ^^^^^^^^^^^^^^^^^^^^^^^^^^^^^^^^^^^^^^^^^^^^^^^^^^^^^^^^^^^^^
  File "/home/airflow/.local/lib/python3.11/site-packages/airflow/models/taskinstance.py", line 432, in _execute_callable
    return execute_callable(context=context, **execute_callable_kwargs)
           ^^^^^^^^^^^^^^^^^^^^^^^^^^^^^^^^^^^^^^^^^^^^^^^^^^^^^^^^^^^^
  File "/home/airflow/.local/lib/python3.11/site-packages/airflow/models/baseoperator.py", line 401, in wrapper
    return func(self, *args, **kwargs)
           ^^^^^^^^^^^^^^^^^^^^^^^^^^^
  File "/home/airflow/.local/lib/python3.11/site-packages/airflow/operators/bash.py", line 243, in execute
    raise AirflowException(
airflow.exceptions.AirflowException: Bash command failed. The command returned a non-zero exit code 1.
[2024-10-30T07:46:14.714+0000] {taskinstance.py:1206} INFO - Marking task as FAILED. dag_id=ETL_To_Data_Warehouse, task_id=update_measure_stage_hongheo, run_id=manual__2024-10-30T07:46:08.221990+00:00, execution_date=20241030T074608, start_date=20241030T074612, end_date=20241030T074614
[2024-10-30T07:46:14.725+0000] {standard_task_runner.py:110} ERROR - Failed to execute job 50 for task update_measure_stage_hongheo (Bash command failed. The command returned a non-zero exit code 1.; 6207)
[2024-10-30T07:46:14.752+0000] {local_task_job_runner.py:240} INFO - Task exited with return code 1
[2024-10-30T07:46:14.936+0000] {taskinstance.py:3503} INFO - 0 downstream tasks scheduled from follow-on schedule check
[2024-10-30T07:46:14.941+0000] {local_task_job_runner.py:222} INFO - ::endgroup::
