[2024-11-12T01:25:46.772+0000] {local_task_job_runner.py:120} INFO - ::group::Pre task execution logs
[2024-11-12T01:25:46.800+0000] {taskinstance.py:2076} INFO - Dependencies all met for dep_context=non-requeueable deps ti=<TaskInstance: ETL_To_Data_Warehouse.load_data_to_stgFact manual__2024-11-12T01:24:54.300922+00:00 [queued]>
[2024-11-12T01:25:46.808+0000] {taskinstance.py:2076} INFO - Dependencies all met for dep_context=requeueable deps ti=<TaskInstance: ETL_To_Data_Warehouse.load_data_to_stgFact manual__2024-11-12T01:24:54.300922+00:00 [queued]>
[2024-11-12T01:25:46.808+0000] {taskinstance.py:2306} INFO - Starting attempt 1 of 1
[2024-11-12T01:25:46.821+0000] {taskinstance.py:2330} INFO - Executing <Task(PythonOperator): load_data_to_stgFact> on 2024-11-12 01:24:54.300922+00:00
[2024-11-12T01:25:46.827+0000] {standard_task_runner.py:63} INFO - Started process 1270 to run task
[2024-11-12T01:25:46.833+0000] {standard_task_runner.py:90} INFO - Running: ['***', 'tasks', 'run', 'ETL_To_Data_Warehouse', 'load_data_to_stgFact', 'manual__2024-11-12T01:24:54.300922+00:00', '--job-id', '616', '--raw', '--subdir', 'DAGS_FOLDER/ETL_LDTBXH.dag.py', '--cfg-path', '/tmp/tmph3ozsh_k']
[2024-11-12T01:25:46.836+0000] {standard_task_runner.py:91} INFO - Job 616: Subtask load_data_to_stgFact
[2024-11-12T01:25:46.882+0000] {task_command.py:426} INFO - Running <TaskInstance: ETL_To_Data_Warehouse.load_data_to_stgFact manual__2024-11-12T01:24:54.300922+00:00 [running]> on host 3d0ab7361361
[2024-11-12T01:25:46.958+0000] {taskinstance.py:2648} INFO - Exporting env vars: AIRFLOW_CTX_DAG_OWNER='***' AIRFLOW_CTX_DAG_ID='ETL_To_Data_Warehouse' AIRFLOW_CTX_TASK_ID='load_data_to_stgFact' AIRFLOW_CTX_EXECUTION_DATE='2024-11-12T01:24:54.300922+00:00' AIRFLOW_CTX_TRY_NUMBER='1' AIRFLOW_CTX_DAG_RUN_ID='manual__2024-11-12T01:24:54.300922+00:00'
[2024-11-12T01:25:46.959+0000] {taskinstance.py:430} INFO - ::endgroup::
[2024-11-12T01:25:46.996+0000] {logging_mixin.py:188} INFO - Kết nối đến MySQL thành công
[2024-11-12T01:25:47.004+0000] {logging_mixin.py:188} INFO - Error fetching data from API: HTTPConnectionPool(host='host.docker.internal', port=8000): Max retries exceeded with url: /BaoCaoNCC (Caused by NewConnectionError('<urllib3.connection.HTTPConnection object at 0x7fb5de2c1d50>: Failed to establish a new connection: [Errno 101] Network is unreachable'))
[2024-11-12T01:25:47.005+0000] {logging_mixin.py:188} INFO - Không có dữ liệu để chèn.
[2024-11-12T01:25:47.005+0000] {python.py:237} INFO - Done. Returned value was: None
[2024-11-12T01:25:47.006+0000] {taskinstance.py:441} INFO - ::group::Post task execution logs
[2024-11-12T01:25:47.016+0000] {taskinstance.py:1206} INFO - Marking task as SUCCESS. dag_id=ETL_To_Data_Warehouse, task_id=load_data_to_stgFact, run_id=manual__2024-11-12T01:24:54.300922+00:00, execution_date=20241112T012454, start_date=20241112T012546, end_date=20241112T012547
[2024-11-12T01:25:47.048+0000] {local_task_job_runner.py:240} INFO - Task exited with return code 0
[2024-11-12T01:25:47.079+0000] {taskinstance.py:3503} INFO - 1 downstream tasks scheduled from follow-on schedule check
[2024-11-12T01:25:47.081+0000] {local_task_job_runner.py:222} INFO - ::endgroup::
