[2024-10-30T07:49:01.765+0000] {local_task_job_runner.py:120} INFO - ::group::Pre task execution logs
[2024-10-30T07:49:01.790+0000] {taskinstance.py:2076} INFO - Dependencies all met for dep_context=non-requeueable deps ti=<TaskInstance: ETL_To_Data_Warehouse.update_measure_stage_hongheo manual__2024-10-30T07:48:55.441610+00:00 [queued]>
[2024-10-30T07:49:01.801+0000] {taskinstance.py:2076} INFO - Dependencies all met for dep_context=requeueable deps ti=<TaskInstance: ETL_To_Data_Warehouse.update_measure_stage_hongheo manual__2024-10-30T07:48:55.441610+00:00 [queued]>
[2024-10-30T07:49:01.801+0000] {taskinstance.py:2306} INFO - Starting attempt 1 of 1
[2024-10-30T07:49:01.817+0000] {taskinstance.py:2330} INFO - Executing <Task(BashOperator): update_measure_stage_hongheo> on 2024-10-30 07:48:55.441610+00:00
[2024-10-30T07:49:01.823+0000] {standard_task_runner.py:63} INFO - Started process 7788 to run task
[2024-10-30T07:49:01.826+0000] {standard_task_runner.py:90} INFO - Running: ['***', 'tasks', 'run', 'ETL_To_Data_Warehouse', 'update_measure_stage_hongheo', 'manual__2024-10-30T07:48:55.441610+00:00', '--job-id', '54', '--raw', '--subdir', 'DAGS_FOLDER/ETL_LDTBXH.dag.py', '--cfg-path', '/tmp/tmp4d3qjryl']
[2024-10-30T07:49:01.828+0000] {standard_task_runner.py:91} INFO - Job 54: Subtask update_measure_stage_hongheo
[2024-10-30T07:49:02.046+0000] {task_command.py:426} INFO - Running <TaskInstance: ETL_To_Data_Warehouse.update_measure_stage_hongheo manual__2024-10-30T07:48:55.441610+00:00 [running]> on host 3d0ab7361361
[2024-10-30T07:49:02.114+0000] {taskinstance.py:2648} INFO - Exporting env vars: AIRFLOW_CTX_DAG_OWNER='***' AIRFLOW_CTX_DAG_ID='ETL_To_Data_Warehouse' AIRFLOW_CTX_TASK_ID='update_measure_stage_hongheo' AIRFLOW_CTX_EXECUTION_DATE='2024-10-30T07:48:55.441610+00:00' AIRFLOW_CTX_TRY_NUMBER='1' AIRFLOW_CTX_DAG_RUN_ID='manual__2024-10-30T07:48:55.441610+00:00'
[2024-10-30T07:49:02.116+0000] {taskinstance.py:430} INFO - ::endgroup::
[2024-10-30T07:49:02.117+0000] {subprocess.py:63} INFO - Tmp dir root location: /tmp
[2024-10-30T07:49:02.118+0000] {subprocess.py:75} INFO - Running command: ['/usr/bin/bash', '-c', 'python /opt/***/plugins/HoNgheo/Transform.py']
[2024-10-30T07:49:02.128+0000] {subprocess.py:86} INFO - Output:
[2024-10-30T07:49:07.302+0000] {subprocess.py:93} INFO - Traceback (most recent call last):
[2024-10-30T07:49:07.303+0000] {subprocess.py:93} INFO -   File "/home/***/.local/lib/python3.11/site-packages/mysql/connector/connection_cext.py", line 327, in _open_connection
[2024-10-30T07:49:07.303+0000] {subprocess.py:93} INFO -     self._cmysql.connect(**cnx_kwargs)
[2024-10-30T07:49:07.304+0000] {subprocess.py:93} INFO - _mysql_connector.MySQLInterfaceError: Unknown MySQL server host 'docker.internal.host' (-2)
[2024-10-30T07:49:07.304+0000] {subprocess.py:93} INFO - 
[2024-10-30T07:49:07.305+0000] {subprocess.py:93} INFO - The above exception was the direct cause of the following exception:
[2024-10-30T07:49:07.305+0000] {subprocess.py:93} INFO - 
[2024-10-30T07:49:07.305+0000] {subprocess.py:93} INFO - Traceback (most recent call last):
[2024-10-30T07:49:07.306+0000] {subprocess.py:93} INFO -   File "/opt/***/plugins/HoNgheo/Transform.py", line 75, in <module>
[2024-10-30T07:49:07.306+0000] {subprocess.py:93} INFO -     run_transform_fact_hongheo()
[2024-10-30T07:49:07.306+0000] {subprocess.py:93} INFO -   File "/opt/***/plugins/HoNgheo/Transform.py", line 22, in run_transform_fact_hongheo
[2024-10-30T07:49:07.308+0000] {subprocess.py:93} INFO -     conn = mysql.connector.connect(
[2024-10-30T07:49:07.308+0000] {subprocess.py:93} INFO -            ^^^^^^^^^^^^^^^^^^^^^^^^
[2024-10-30T07:49:07.308+0000] {subprocess.py:93} INFO -   File "/home/***/.local/lib/python3.11/site-packages/mysql/connector/pooling.py", line 322, in connect
[2024-10-30T07:49:07.309+0000] {subprocess.py:93} INFO -     return CMySQLConnection(*args, **kwargs)
[2024-10-30T07:49:07.309+0000] {subprocess.py:93} INFO -            ^^^^^^^^^^^^^^^^^^^^^^^^^^^^^^^^^
[2024-10-30T07:49:07.310+0000] {subprocess.py:93} INFO -   File "/home/***/.local/lib/python3.11/site-packages/mysql/connector/connection_cext.py", line 144, in __init__
[2024-10-30T07:49:07.310+0000] {subprocess.py:93} INFO -     self.connect(**kwargs)
[2024-10-30T07:49:07.310+0000] {subprocess.py:93} INFO -   File "/home/***/.local/lib/python3.11/site-packages/mysql/connector/abstracts.py", line 1360, in connect
[2024-10-30T07:49:07.311+0000] {subprocess.py:93} INFO -     self._open_connection()
[2024-10-30T07:49:07.312+0000] {subprocess.py:93} INFO -   File "/home/***/.local/lib/python3.11/site-packages/mysql/connector/connection_cext.py", line 332, in _open_connection
[2024-10-30T07:49:07.312+0000] {subprocess.py:93} INFO -     raise get_mysql_exception(
[2024-10-30T07:49:07.312+0000] {subprocess.py:93} INFO - mysql.connector.errors.DatabaseError: 2005 (HY000): Unknown MySQL server host 'docker.internal.host' (-2)
[2024-10-30T07:49:07.426+0000] {subprocess.py:97} INFO - Command exited with return code 1
[2024-10-30T07:49:07.427+0000] {taskinstance.py:441} INFO - ::group::Post task execution logs
[2024-10-30T07:49:07.436+0000] {taskinstance.py:2905} ERROR - Task failed with exception
Traceback (most recent call last):
  File "/home/airflow/.local/lib/python3.11/site-packages/airflow/models/taskinstance.py", line 465, in _execute_task
    result = _execute_callable(context=context, **execute_callable_kwargs)
             ^^^^^^^^^^^^^^^^^^^^^^^^^^^^^^^^^^^^^^^^^^^^^^^^^^^^^^^^^^^^^
  File "/home/airflow/.local/lib/python3.11/site-packages/airflow/models/taskinstance.py", line 432, in _execute_callable
    return execute_callable(context=context, **execute_callable_kwargs)
           ^^^^^^^^^^^^^^^^^^^^^^^^^^^^^^^^^^^^^^^^^^^^^^^^^^^^^^^^^^^^
  File "/home/airflow/.local/lib/python3.11/site-packages/airflow/models/baseoperator.py", line 401, in wrapper
    return func(self, *args, **kwargs)
           ^^^^^^^^^^^^^^^^^^^^^^^^^^^
  File "/home/airflow/.local/lib/python3.11/site-packages/airflow/operators/bash.py", line 243, in execute
    raise AirflowException(
airflow.exceptions.AirflowException: Bash command failed. The command returned a non-zero exit code 1.
[2024-10-30T07:49:07.440+0000] {taskinstance.py:1206} INFO - Marking task as FAILED. dag_id=ETL_To_Data_Warehouse, task_id=update_measure_stage_hongheo, run_id=manual__2024-10-30T07:48:55.441610+00:00, execution_date=20241030T074855, start_date=20241030T074901, end_date=20241030T074907
[2024-10-30T07:49:07.451+0000] {standard_task_runner.py:110} ERROR - Failed to execute job 54 for task update_measure_stage_hongheo (Bash command failed. The command returned a non-zero exit code 1.; 7788)
[2024-10-30T07:49:07.470+0000] {local_task_job_runner.py:240} INFO - Task exited with return code 1
[2024-10-30T07:49:07.487+0000] {taskinstance.py:3503} INFO - 0 downstream tasks scheduled from follow-on schedule check
[2024-10-30T07:49:07.491+0000] {local_task_job_runner.py:222} INFO - ::endgroup::
