[2024-11-05T16:04:19.639+0000] {local_task_job_runner.py:120} INFO - ::group::Pre task execution logs
[2024-11-05T16:04:19.669+0000] {taskinstance.py:2076} INFO - Dependencies all met for dep_context=non-requeueable deps ti=<TaskInstance: ETL_To_Data_Warehouse.load_data_to_Stg_DimBenef manual__2024-11-05T16:04:12.650719+00:00 [queued]>
[2024-11-05T16:04:19.681+0000] {taskinstance.py:2076} INFO - Dependencies all met for dep_context=requeueable deps ti=<TaskInstance: ETL_To_Data_Warehouse.load_data_to_Stg_DimBenef manual__2024-11-05T16:04:12.650719+00:00 [queued]>
[2024-11-05T16:04:19.682+0000] {taskinstance.py:2306} INFO - Starting attempt 1 of 1
[2024-11-05T16:04:19.696+0000] {taskinstance.py:2330} INFO - Executing <Task(BashOperator): load_data_to_Stg_DimBenef> on 2024-11-05 16:04:12.650719+00:00
[2024-11-05T16:04:19.703+0000] {standard_task_runner.py:63} INFO - Started process 19784 to run task
[2024-11-05T16:04:19.707+0000] {standard_task_runner.py:90} INFO - Running: ['***', 'tasks', 'run', 'ETL_To_Data_Warehouse', 'load_data_to_Stg_DimBenef', 'manual__2024-11-05T16:04:12.650719+00:00', '--job-id', '327', '--raw', '--subdir', 'DAGS_FOLDER/ETL_LDTBXH.dag.py', '--cfg-path', '/tmp/tmpoufq19i1']
[2024-11-05T16:04:19.708+0000] {standard_task_runner.py:91} INFO - Job 327: Subtask load_data_to_Stg_DimBenef
[2024-11-05T16:04:19.758+0000] {task_command.py:426} INFO - Running <TaskInstance: ETL_To_Data_Warehouse.load_data_to_Stg_DimBenef manual__2024-11-05T16:04:12.650719+00:00 [running]> on host 3d0ab7361361
[2024-11-05T16:04:20.091+0000] {taskinstance.py:2648} INFO - Exporting env vars: AIRFLOW_CTX_DAG_OWNER='***' AIRFLOW_CTX_DAG_ID='ETL_To_Data_Warehouse' AIRFLOW_CTX_TASK_ID='load_data_to_Stg_DimBenef' AIRFLOW_CTX_EXECUTION_DATE='2024-11-05T16:04:12.650719+00:00' AIRFLOW_CTX_TRY_NUMBER='1' AIRFLOW_CTX_DAG_RUN_ID='manual__2024-11-05T16:04:12.650719+00:00'
[2024-11-05T16:04:20.093+0000] {taskinstance.py:430} INFO - ::endgroup::
[2024-11-05T16:04:20.094+0000] {subprocess.py:63} INFO - Tmp dir root location: /tmp
[2024-11-05T16:04:20.095+0000] {subprocess.py:75} INFO - Running command: ['/usr/bin/bash', '-c', 'python -m opt/***/plugins/NCC/load_api_to_stgBenef']
[2024-11-05T16:04:20.109+0000] {subprocess.py:86} INFO - Output:
[2024-11-05T16:04:20.189+0000] {subprocess.py:93} INFO - /home/***/.local/bin/python: No module named opt/***/plugins/NCC/load_api_to_stgBenef
[2024-11-05T16:04:20.193+0000] {subprocess.py:97} INFO - Command exited with return code 1
[2024-11-05T16:04:20.194+0000] {taskinstance.py:441} INFO - ::group::Post task execution logs
[2024-11-05T16:04:20.204+0000] {taskinstance.py:2905} ERROR - Task failed with exception
Traceback (most recent call last):
  File "/home/airflow/.local/lib/python3.11/site-packages/airflow/models/taskinstance.py", line 465, in _execute_task
    result = _execute_callable(context=context, **execute_callable_kwargs)
             ^^^^^^^^^^^^^^^^^^^^^^^^^^^^^^^^^^^^^^^^^^^^^^^^^^^^^^^^^^^^^
  File "/home/airflow/.local/lib/python3.11/site-packages/airflow/models/taskinstance.py", line 432, in _execute_callable
    return execute_callable(context=context, **execute_callable_kwargs)
           ^^^^^^^^^^^^^^^^^^^^^^^^^^^^^^^^^^^^^^^^^^^^^^^^^^^^^^^^^^^^
  File "/home/airflow/.local/lib/python3.11/site-packages/airflow/models/baseoperator.py", line 401, in wrapper
    return func(self, *args, **kwargs)
           ^^^^^^^^^^^^^^^^^^^^^^^^^^^
  File "/home/airflow/.local/lib/python3.11/site-packages/airflow/operators/bash.py", line 243, in execute
    raise AirflowException(
airflow.exceptions.AirflowException: Bash command failed. The command returned a non-zero exit code 1.
[2024-11-05T16:04:20.208+0000] {taskinstance.py:1206} INFO - Marking task as FAILED. dag_id=ETL_To_Data_Warehouse, task_id=load_data_to_Stg_DimBenef, run_id=manual__2024-11-05T16:04:12.650719+00:00, execution_date=20241105T160412, start_date=20241105T160419, end_date=20241105T160420
[2024-11-05T16:04:20.221+0000] {standard_task_runner.py:110} ERROR - Failed to execute job 327 for task load_data_to_Stg_DimBenef (Bash command failed. The command returned a non-zero exit code 1.; 19784)
[2024-11-05T16:04:20.240+0000] {local_task_job_runner.py:240} INFO - Task exited with return code 1
[2024-11-05T16:04:20.269+0000] {taskinstance.py:3503} INFO - 0 downstream tasks scheduled from follow-on schedule check
[2024-11-05T16:04:20.274+0000] {local_task_job_runner.py:222} INFO - ::endgroup::
