[2024-10-30T08:05:44.193+0000] {local_task_job_runner.py:120} INFO - ::group::Pre task execution logs
[2024-10-30T08:05:44.219+0000] {taskinstance.py:2076} INFO - Dependencies all met for dep_context=non-requeueable deps ti=<TaskInstance: ETL_To_Data_Warehouse.update_measure_stage_hongheo manual__2024-10-30T08:05:38.122219+00:00 [queued]>
[2024-10-30T08:05:44.229+0000] {taskinstance.py:2076} INFO - Dependencies all met for dep_context=requeueable deps ti=<TaskInstance: ETL_To_Data_Warehouse.update_measure_stage_hongheo manual__2024-10-30T08:05:38.122219+00:00 [queued]>
[2024-10-30T08:05:44.230+0000] {taskinstance.py:2306} INFO - Starting attempt 1 of 1
[2024-10-30T08:05:44.243+0000] {taskinstance.py:2330} INFO - Executing <Task(PythonOperator): update_measure_stage_hongheo> on 2024-10-30 08:05:38.122219+00:00
[2024-10-30T08:05:44.250+0000] {standard_task_runner.py:63} INFO - Started process 16657 to run task
[2024-10-30T08:05:44.252+0000] {standard_task_runner.py:90} INFO - Running: ['***', 'tasks', 'run', 'ETL_To_Data_Warehouse', 'update_measure_stage_hongheo', 'manual__2024-10-30T08:05:38.122219+00:00', '--job-id', '70', '--raw', '--subdir', 'DAGS_FOLDER/ETL_LDTBXH.dag.py', '--cfg-path', '/tmp/tmp1p7oq0it']
[2024-10-30T08:05:44.253+0000] {standard_task_runner.py:91} INFO - Job 70: Subtask update_measure_stage_hongheo
[2024-10-30T08:05:44.298+0000] {task_command.py:426} INFO - Running <TaskInstance: ETL_To_Data_Warehouse.update_measure_stage_hongheo manual__2024-10-30T08:05:38.122219+00:00 [running]> on host 3d0ab7361361
[2024-10-30T08:05:44.375+0000] {taskinstance.py:2648} INFO - Exporting env vars: AIRFLOW_CTX_DAG_OWNER='***' AIRFLOW_CTX_DAG_ID='ETL_To_Data_Warehouse' AIRFLOW_CTX_TASK_ID='update_measure_stage_hongheo' AIRFLOW_CTX_EXECUTION_DATE='2024-10-30T08:05:38.122219+00:00' AIRFLOW_CTX_TRY_NUMBER='1' AIRFLOW_CTX_DAG_RUN_ID='manual__2024-10-30T08:05:38.122219+00:00'
[2024-10-30T08:05:44.377+0000] {taskinstance.py:430} INFO - ::endgroup::
[2024-10-30T08:05:44.468+0000] {logging_mixin.py:188} WARNING - /opt/***/plugins/HoNgheo/Transform.py:52 UserWarning: pandas only supports SQLAlchemy connectable (engine/connection) or database string URI or sqlite3 DBAPI2 connection. Other DBAPI2 objects are not tested. Please consider using SQLAlchemy.
[2024-10-30T08:05:44.488+0000] {taskinstance.py:441} INFO - ::group::Post task execution logs
[2024-10-30T08:05:44.488+0000] {taskinstance.py:2905} ERROR - Task failed with exception
Traceback (most recent call last):
  File "/home/airflow/.local/lib/python3.11/site-packages/pandas/core/indexes/base.py", line 3791, in get_loc
    return self._engine.get_loc(casted_key)
           ^^^^^^^^^^^^^^^^^^^^^^^^^^^^^^^^
  File "index.pyx", line 152, in pandas._libs.index.IndexEngine.get_loc
  File "index.pyx", line 181, in pandas._libs.index.IndexEngine.get_loc
  File "pandas/_libs/hashtable_class_helper.pxi", line 7080, in pandas._libs.hashtable.PyObjectHashTable.get_item
  File "pandas/_libs/hashtable_class_helper.pxi", line 7088, in pandas._libs.hashtable.PyObjectHashTable.get_item
KeyError: 'ID_HoGiaDinh'

The above exception was the direct cause of the following exception:

Traceback (most recent call last):
  File "/home/airflow/.local/lib/python3.11/site-packages/airflow/models/taskinstance.py", line 465, in _execute_task
    result = _execute_callable(context=context, **execute_callable_kwargs)
             ^^^^^^^^^^^^^^^^^^^^^^^^^^^^^^^^^^^^^^^^^^^^^^^^^^^^^^^^^^^^^
  File "/home/airflow/.local/lib/python3.11/site-packages/airflow/models/taskinstance.py", line 432, in _execute_callable
    return execute_callable(context=context, **execute_callable_kwargs)
           ^^^^^^^^^^^^^^^^^^^^^^^^^^^^^^^^^^^^^^^^^^^^^^^^^^^^^^^^^^^^
  File "/home/airflow/.local/lib/python3.11/site-packages/airflow/models/baseoperator.py", line 401, in wrapper
    return func(self, *args, **kwargs)
           ^^^^^^^^^^^^^^^^^^^^^^^^^^^
  File "/home/airflow/.local/lib/python3.11/site-packages/airflow/operators/python.py", line 235, in execute
    return_value = self.execute_callable()
                   ^^^^^^^^^^^^^^^^^^^^^^^
  File "/home/airflow/.local/lib/python3.11/site-packages/airflow/operators/python.py", line 252, in execute_callable
    return self.python_callable(*self.op_args, **self.op_kwargs)
           ^^^^^^^^^^^^^^^^^^^^^^^^^^^^^^^^^^^^^^^^^^^^^^^^^^^^^
  File "/opt/airflow/plugins/HoNgheo/Transform.py", line 67, in run_transform_fact_hongheo
    cursor.execute(update_query, (row['TongDiemB1B2'], row['KetQuaCuoiCung'], row['ID_HoGiaDinh']))
                                                                              ~~~^^^^^^^^^^^^^^^^
  File "/home/airflow/.local/lib/python3.11/site-packages/pandas/core/series.py", line 1040, in __getitem__
    return self._get_value(key)
           ^^^^^^^^^^^^^^^^^^^^
  File "/home/airflow/.local/lib/python3.11/site-packages/pandas/core/series.py", line 1156, in _get_value
    loc = self.index.get_loc(label)
          ^^^^^^^^^^^^^^^^^^^^^^^^^
  File "/home/airflow/.local/lib/python3.11/site-packages/pandas/core/indexes/base.py", line 3798, in get_loc
    raise KeyError(key) from err
KeyError: 'ID_HoGiaDinh'
[2024-10-30T08:05:44.503+0000] {taskinstance.py:1206} INFO - Marking task as FAILED. dag_id=ETL_To_Data_Warehouse, task_id=update_measure_stage_hongheo, run_id=manual__2024-10-30T08:05:38.122219+00:00, execution_date=20241030T080538, start_date=20241030T080544, end_date=20241030T080544
[2024-10-30T08:05:44.516+0000] {standard_task_runner.py:110} ERROR - Failed to execute job 70 for task update_measure_stage_hongheo ('ID_HoGiaDinh'; 16657)
[2024-10-30T08:05:44.545+0000] {local_task_job_runner.py:240} INFO - Task exited with return code 1
[2024-10-30T08:05:44.572+0000] {taskinstance.py:3503} INFO - 0 downstream tasks scheduled from follow-on schedule check
[2024-10-30T08:05:44.577+0000] {local_task_job_runner.py:222} INFO - ::endgroup::
